[2025-06-07T15:32:15.559+0000] {local_task_job_runner.py:123} INFO - ::group::Pre task execution logs
[2025-06-07T15:32:15.572+0000] {taskinstance.py:2613} INFO - Dependencies all met for dep_context=non-requeueable deps ti=<TaskInstance: stephen_curry_stats_medallion_etl.ensure_bucket_exists manual__2025-06-07T15:32:14.926526+00:00 [queued]>
[2025-06-07T15:32:15.578+0000] {taskinstance.py:2613} INFO - Dependencies all met for dep_context=requeueable deps ti=<TaskInstance: stephen_curry_stats_medallion_etl.ensure_bucket_exists manual__2025-06-07T15:32:14.926526+00:00 [queued]>
[2025-06-07T15:32:15.578+0000] {taskinstance.py:2866} INFO - Starting attempt 1 of 1
[2025-06-07T15:32:15.590+0000] {taskinstance.py:2889} INFO - Executing <Task(PythonOperator): ensure_bucket_exists> on 2025-06-07 15:32:14.926526+00:00
[2025-06-07T15:32:15.593+0000] {standard_task_runner.py:72} INFO - Started process 199 to run task
[2025-06-07T15:32:15.595+0000] {standard_task_runner.py:104} INFO - Running: ['***', 'tasks', 'run', 'stephen_curry_stats_medallion_etl', 'ensure_bucket_exists', 'manual__2025-06-07T15:32:14.926526+00:00', '--job-id', '2', '--raw', '--subdir', 'DAGS_FOLDER/medallion_sales_etl_dag.py', '--cfg-path', '/tmp/tmp6jevm8qf']
[2025-06-07T15:32:15.597+0000] {standard_task_runner.py:105} INFO - Job 2: Subtask ensure_bucket_exists
[2025-06-07T15:32:15.628+0000] {task_command.py:467} INFO - Running <TaskInstance: stephen_curry_stats_medallion_etl.ensure_bucket_exists manual__2025-06-07T15:32:14.926526+00:00 [running]> on host a8930d57bcb9
[2025-06-07T15:32:15.678+0000] {taskinstance.py:3132} INFO - Exporting env vars: AIRFLOW_CTX_DAG_OWNER='***' AIRFLOW_CTX_DAG_ID='stephen_curry_stats_medallion_etl' AIRFLOW_CTX_TASK_ID='ensure_bucket_exists' AIRFLOW_CTX_EXECUTION_DATE='2025-06-07T15:32:14.926526+00:00' AIRFLOW_CTX_TRY_NUMBER='1' AIRFLOW_CTX_DAG_RUN_ID='manual__2025-06-07T15:32:14.926526+00:00'
[2025-06-07T15:32:15.679+0000] {taskinstance.py:731} INFO - ::endgroup::
[2025-06-07T15:32:15.700+0000] {logging_mixin.py:190} INFO - Bucket 'mybucket' not found. Creating it...
[2025-06-07T15:32:15.746+0000] {logging_mixin.py:190} INFO - Error checking or creating bucket 'mybucket': S3 operation failed; code: BucketAlreadyOwnedByYou, message: Your previous request to create the named bucket succeeded and you already own it., resource: /mybucket, request_id: 1846CC7B695D2E10, host_id: dd9025bab4ad464b049177c95eb6ebf374d3b3fd1af9251148b658df7ac2e3e8, bucket_name: mybucket
[2025-06-07T15:32:15.747+0000] {taskinstance.py:3311} ERROR - Task failed with exception
Traceback (most recent call last):
  File "/home/airflow/.local/lib/python3.11/site-packages/airflow/models/taskinstance.py", line 767, in _execute_task
    result = _execute_callable(context=context, **execute_callable_kwargs)
             ^^^^^^^^^^^^^^^^^^^^^^^^^^^^^^^^^^^^^^^^^^^^^^^^^^^^^^^^^^^^^
  File "/home/airflow/.local/lib/python3.11/site-packages/airflow/models/taskinstance.py", line 733, in _execute_callable
    return ExecutionCallableRunner(
           ^^^^^^^^^^^^^^^^^^^^^^^^
  File "/home/airflow/.local/lib/python3.11/site-packages/airflow/utils/operator_helpers.py", line 252, in run
    return self.func(*args, **kwargs)
           ^^^^^^^^^^^^^^^^^^^^^^^^^^
  File "/home/airflow/.local/lib/python3.11/site-packages/airflow/models/baseoperator.py", line 417, in wrapper
    return func(self, *args, **kwargs)
           ^^^^^^^^^^^^^^^^^^^^^^^^^^^
  File "/home/airflow/.local/lib/python3.11/site-packages/airflow/operators/python.py", line 238, in execute
    return_value = self.execute_callable()
                   ^^^^^^^^^^^^^^^^^^^^^^^
  File "/home/airflow/.local/lib/python3.11/site-packages/airflow/operators/python.py", line 256, in execute_callable
    return runner.run(*self.op_args, **self.op_kwargs)
           ^^^^^^^^^^^^^^^^^^^^^^^^^^^^^^^^^^^^^^^^^^^
  File "/home/airflow/.local/lib/python3.11/site-packages/airflow/utils/operator_helpers.py", line 252, in run
    return self.func(*args, **kwargs)
           ^^^^^^^^^^^^^^^^^^^^^^^^^^
  File "/opt/airflow/include/custom_utils/minio_utils.py", line 27, in ensure_bucket_exists
    client.make_bucket(bucket_name)
  File "/home/airflow/.local/lib/python3.11/site-packages/minio/api.py", line 657, in make_bucket
    self._url_open(
  File "/home/airflow/.local/lib/python3.11/site-packages/minio/api.py", line 424, in _url_open
    raise response_error
minio.error.S3Error: S3 operation failed; code: BucketAlreadyOwnedByYou, message: Your previous request to create the named bucket succeeded and you already own it., resource: /mybucket, request_id: 1846CC7B695D2E10, host_id: dd9025bab4ad464b049177c95eb6ebf374d3b3fd1af9251148b658df7ac2e3e8, bucket_name: mybucket
[2025-06-07T15:32:15.755+0000] {taskinstance.py:1225} INFO - Marking task as FAILED. dag_id=stephen_curry_stats_medallion_etl, task_id=ensure_bucket_exists, run_id=manual__2025-06-07T15:32:14.926526+00:00, execution_date=20250607T153214, start_date=20250607T153215, end_date=20250607T153215
[2025-06-07T15:32:15.760+0000] {taskinstance.py:340} INFO - ::group::Post task execution logs
[2025-06-07T15:32:15.763+0000] {standard_task_runner.py:124} ERROR - Failed to execute job 2 for task ensure_bucket_exists (S3 operation failed; code: BucketAlreadyOwnedByYou, message: Your previous request to create the named bucket succeeded and you already own it., resource: /mybucket, request_id: 1846CC7B695D2E10, host_id: dd9025bab4ad464b049177c95eb6ebf374d3b3fd1af9251148b658df7ac2e3e8, bucket_name: mybucket; 199)
Traceback (most recent call last):
  File "/home/airflow/.local/lib/python3.11/site-packages/airflow/task/task_runner/standard_task_runner.py", line 117, in _start_by_fork
    ret = args.func(args, dag=self.dag)
          ^^^^^^^^^^^^^^^^^^^^^^^^^^^^^
  File "/home/airflow/.local/lib/python3.11/site-packages/airflow/cli/cli_config.py", line 49, in command
    return func(*args, **kwargs)
           ^^^^^^^^^^^^^^^^^^^^^
  File "/home/airflow/.local/lib/python3.11/site-packages/airflow/utils/cli.py", line 116, in wrapper
    return f(*args, **kwargs)
           ^^^^^^^^^^^^^^^^^^
  File "/home/airflow/.local/lib/python3.11/site-packages/airflow/cli/commands/task_command.py", line 483, in task_run
    task_return_code = _run_task_by_selected_method(args, _dag, ti)
                       ^^^^^^^^^^^^^^^^^^^^^^^^^^^^^^^^^^^^^^^^^^^^
  File "/home/airflow/.local/lib/python3.11/site-packages/airflow/cli/commands/task_command.py", line 256, in _run_task_by_selected_method
    return _run_raw_task(args, ti)
           ^^^^^^^^^^^^^^^^^^^^^^^
  File "/home/airflow/.local/lib/python3.11/site-packages/airflow/cli/commands/task_command.py", line 341, in _run_raw_task
    return ti._run_raw_task(
           ^^^^^^^^^^^^^^^^^
  File "/home/airflow/.local/lib/python3.11/site-packages/airflow/utils/session.py", line 97, in wrapper
    return func(*args, session=session, **kwargs)
           ^^^^^^^^^^^^^^^^^^^^^^^^^^^^^^^^^^^^^^
  File "/home/airflow/.local/lib/python3.11/site-packages/airflow/models/taskinstance.py", line 3005, in _run_raw_task
    return _run_raw_task(
           ^^^^^^^^^^^^^^
  File "/home/airflow/.local/lib/python3.11/site-packages/airflow/models/taskinstance.py", line 273, in _run_raw_task
    TaskInstance._execute_task_with_callbacks(
  File "/home/airflow/.local/lib/python3.11/site-packages/airflow/models/taskinstance.py", line 3159, in _execute_task_with_callbacks
    result = self._execute_task(context, task_orig)
             ^^^^^^^^^^^^^^^^^^^^^^^^^^^^^^^^^^^^^^
  File "/home/airflow/.local/lib/python3.11/site-packages/airflow/models/taskinstance.py", line 3183, in _execute_task
    return _execute_task(self, context, task_orig)
           ^^^^^^^^^^^^^^^^^^^^^^^^^^^^^^^^^^^^^^^
  File "/home/airflow/.local/lib/python3.11/site-packages/airflow/models/taskinstance.py", line 767, in _execute_task
    result = _execute_callable(context=context, **execute_callable_kwargs)
             ^^^^^^^^^^^^^^^^^^^^^^^^^^^^^^^^^^^^^^^^^^^^^^^^^^^^^^^^^^^^^
  File "/home/airflow/.local/lib/python3.11/site-packages/airflow/models/taskinstance.py", line 733, in _execute_callable
    return ExecutionCallableRunner(
           ^^^^^^^^^^^^^^^^^^^^^^^^
  File "/home/airflow/.local/lib/python3.11/site-packages/airflow/utils/operator_helpers.py", line 252, in run
    return self.func(*args, **kwargs)
           ^^^^^^^^^^^^^^^^^^^^^^^^^^
  File "/home/airflow/.local/lib/python3.11/site-packages/airflow/models/baseoperator.py", line 417, in wrapper
    return func(self, *args, **kwargs)
           ^^^^^^^^^^^^^^^^^^^^^^^^^^^
  File "/home/airflow/.local/lib/python3.11/site-packages/airflow/operators/python.py", line 238, in execute
    return_value = self.execute_callable()
                   ^^^^^^^^^^^^^^^^^^^^^^^
  File "/home/airflow/.local/lib/python3.11/site-packages/airflow/operators/python.py", line 256, in execute_callable
    return runner.run(*self.op_args, **self.op_kwargs)
           ^^^^^^^^^^^^^^^^^^^^^^^^^^^^^^^^^^^^^^^^^^^
  File "/home/airflow/.local/lib/python3.11/site-packages/airflow/utils/operator_helpers.py", line 252, in run
    return self.func(*args, **kwargs)
           ^^^^^^^^^^^^^^^^^^^^^^^^^^
  File "/opt/airflow/include/custom_utils/minio_utils.py", line 27, in ensure_bucket_exists
    client.make_bucket(bucket_name)
  File "/home/airflow/.local/lib/python3.11/site-packages/minio/api.py", line 657, in make_bucket
    self._url_open(
  File "/home/airflow/.local/lib/python3.11/site-packages/minio/api.py", line 424, in _url_open
    raise response_error
minio.error.S3Error: S3 operation failed; code: BucketAlreadyOwnedByYou, message: Your previous request to create the named bucket succeeded and you already own it., resource: /mybucket, request_id: 1846CC7B695D2E10, host_id: dd9025bab4ad464b049177c95eb6ebf374d3b3fd1af9251148b658df7ac2e3e8, bucket_name: mybucket
[2025-06-07T15:32:15.776+0000] {local_task_job_runner.py:266} INFO - Task exited with return code 1
[2025-06-07T15:32:15.793+0000] {taskinstance.py:3895} INFO - 0 downstream tasks scheduled from follow-on schedule check
[2025-06-07T15:32:15.796+0000] {local_task_job_runner.py:245} INFO - ::endgroup::
